Workbook

Sheet All WH Stock Status
H1: Monthly Demand | M1: Critical Items
B2: Category | C2: Item Code | D2: Item Description | E2: Packing | F2: UOM | G2: Conversion | H2: QTY in Pack | I2: QTY in Unit | J2: Lead Time | K2: Reordering Point | L2: WH Stocks | M2: Coverage/Day | N2: 0rder Status | O2: Criticality | R2: Category | S2: Stock Status
A3: 168 | B3: طباعة وتغليف - Packaging | C3: PM-00638 | D3: Caramelized Pecan Paper Box 1 PCS (New ID) | علبة بيكان مكرمل ورقية | E3: 1 Box X 600 | F3: Box | G3: 0.0016666667 | H3: =VLOOKUP($C3,'Master File June-26'!$C$3:$L$670,6,0) -> 13 | I3: =VLOOKUP($C3,'Master File June-26'!$C$3:$L$670,7,0) -> 7800 | J3: =VLOOKUP($C3,'Master File June-26'!$C$3:$L$670,8,0) -> 14 | K3: =VLOOKUP($C3,'Master File June-26'!$C$3:$L$670,9,0) -> 3900 | L3: =VLOOKUP($C3,'Master File June-26'!$C$3:$L$670,10,0) -> 0 | M3: =IFERROR((L3/I3*30),0) -> 0 | N3: =IF(M3<J3,"ORDER NOW","IN STOCK") -> ORDER NOW | O3: =IF(M3<J3,"CRITICAL","FOLLOW UP DELIVERY") -> CRITICAL | S3: =IF(L3<K3,0,1) -> 0
A4: 94 | B4: طباعة وتغليف - Packaging | C4: PM-00200 | D4: Season Paper cup Double 12 Oz ( BREEHANT ) كوب ورقي 12 اونصه تصميم موسمي ( بريهانت ) | E4: 1 Box X 500 | F4: Box | G4: 0.002 | H4: =VLOOKUP($C4,'Master File June-26'!$C$3:$L$670,6,0) -> 8 | I4: =VLOOKUP($C4,'Master File June-26'!$C$3:$L$670,7,0) -> 4000 | J4: =VLOOKUP($C4,'Master File June-26'!$C$3:$L$670,8,0) -> 14 | K4: =VLOOKUP($C4,'Master File June-26'!$C$3:$L$670,9,0) -> 2000 | L4: =VLOOKUP($C4,'Master File June-26'!$C$3:$L$670,10,0) -> 19000 | M4: =IFERROR((L4/I4*30),0) -> 142.5 | N4: =IF(M4<J4,"ORDER NOW","IN STOCK") -> IN STOCK | O4: =IF(M4<J4,"CRITICAL","FOLLOW UP DELIVERY") -> FOLLOW UP DELIVERY | R4: B | S4: =IF(L4<K4,0,1) -> 1
A5: 54 | B5: طباعة وتغليف - Packaging | C5: PM-00669 | D5: سليف ايس تي خوخ | E5: 1 Box X 1200 Pcs | F5: Box | G5: =1/1200 -> 0.00083333333 | H5: =VLOOKUP($C5,'Master File June-26'!$C$3:$L$670,6,0) -> 10 | I5: =VLOOKUP($C5,'Master File June-26'!$C$3:$L$670,7,0) -> 12000 | J5: =VLOOKUP($C5,'Master File June-26'!$C$3:$L$670,8,0) -> 14 | K5: =VLOOKUP($C5,'Master File June-26'!$C$3:$L$670,9,0) -> 6000 | L5: =VLOOKUP($C5,'Master File June-26'!$C$3:$L$670,10,0) -> 0 | M5: =IFERROR((L5/I5*30),0) -> 0 | N5: =IF(M5<J5,"ORDER NOW","IN STOCK") -> ORDER NOW | O5: =IF(M5<J5,"CRITICAL","FOLLOW UP DELIVERY") -> CRITICAL | R5: A | S5: =IF(L5<K5,0,1) -> 0
A6: 178 | B6: طباعة وتغليف - Packaging | C6: PM-00043 | D6: كيس بلاستيك ضبابي مطبوع مع استيكر اغلاق 10 كيلو (التاندو)Printed foggy plastic bag with sticker closure (Tando) | E6: Box | F6: Box | G6: 1 | H6: =VLOOKUP($C6,'Master File June-26'!$C$3:$L$670,6,0) -> 8 | I6: =VLOOKUP($C6,'Master File June-26'!$C$3:$L$670,7,0) -> 3840 | J6: =VLOOKUP($C6,'Master File June-26'!$C$3:$L$670,8,0) -> 14 | K6: =VLOOKUP($C6,'Master File June-26'!$C$3:$L$670,9,0) -> 1920 | L6: =VLOOKUP($C6,'Master File June-26'!$C$3:$L$670,10,0) -> 0 | M6: =IFERROR((L6/I6*30),0) -> 0 | N6: =IF(M6<J6,"ORDER NOW","IN STOCK") -> ORDER NOW | O6: =IF(M6<J6,"CRITICAL","FOLLOW UP DELIVERY") -> CRITICAL | S6: =IF(L6<K6,0,1) -> 0
A7: 93 | B7: طباعة وتغليف - Packaging | C7: PM-00653 | D7: Cup 7 oz double wide Seasnal ( Breehant ) - كوب 7 اونص دبل فتحة واسعه موسمى ( بريهانت ) | E7: 1 Box 20 Pack X 25 Pcs | F7: Box | G7: 0.002 | H7: =VLOOKUP($C7,'Master File June-26'!$C$3:$L$670,6,0) -> 150 | I7: =VLOOKUP($C7,'Master File June-26'!$C$3:$L$670,7,0) -> 75000 | J7: =VLOOKUP($C7,'Master File June-26'!$C$3:$L$670,8,0) -> 14 | K7: =VLOOKUP($C7,'Master File June-26'!$C$3:$L$670,9,0) -> 37500 | L7: =VLOOKUP($C7,'Master File June-26'!$C$3:$L$670,10,0) -> 0 | M7: =IFERROR((L7/I7*30),0) -> 0 | N7: =IF(M7<J7,"ORDER NOW","IN STOCK") -> ORDER NOW | O7: =IF(M7<J7,"CRITICAL","FOLLOW UP DELIVERY") -> CRITICAL | R7: B | S7: =IF(L7<K7,0,1) -> 0
A8: 173 | B8: طباعة وتغليف - Packaging | C8: PM-00296 | D8: Aluminium foil قصدير | E8: Box | F8: Box | G8: 1 | H8: =VLOOKUP($C8,'Master File June-26'!$C$3:$L$670,6,0) -> 2 | I8: =VLOOKUP($C8,'Master File June-26'!$C$3:$L$670,7,0) -> 2 | J8: =VLOOKUP($C8,'Master File June-26'!$C$3:$L$670,8,0) -> 14 | K8: =VLOOKUP($C8,'Master File June-26'!$C$3:$L$670,9,0) -> 1 | L8: =VLOOKUP($C8,'Master File June-26'!$C$3:$L$670,10,0) -> 0 | M8: =IFERROR((L8/I8*30),0) -> 0 | N8: =IF(M8<J8,"ORDER NOW","IN STOCK") -> ORDER NOW | O8: =IF(M8<J8,"CRITICAL","FOLLOW UP DELIVERY") -> CRITICAL | S8: =IF(L8<K8,0,1) -> 0
A9: 539 | B9: Dry Goods - منتجات جافة | C9: RM-00502 | D9: Sugar Jaggery Vijay سكر جاجيري مدور | E9: Box | F9: Box | G9: 1 | H9: =VLOOKUP($C9,'Master File June-26'!$C$3:$L$670,6,0) -> 2 | I9: =VLOOKUP($C9,'Master File June-26'!$C$3:$L$670,7,0) -> 2 | J9: =VLOOKUP($C9,'Master File June-26'!$C$3:$L$670,8,0) -> 14 | K9: =VLOOKUP($C9,'Master File June-26'!$C$3:$L$670,9,0) -> 1 | L9: =VLOOKUP($C9,'Master File June-26'!$C$3:$L$670,10,0) -> 0 | M9: =IFERROR((L9/I9*30),0) -> 0 | N9: =IF(M9<J9,"ORDER NOW","IN STOCK") -> ORDER NOW | O9: =IF(M9<J9,"CRITICAL","FOLLOW UP DELIVERY") -> CRITICAL | S9: =IF(L9<K9,0,1) -> 0
A10: 557 | B10: Dry Goods - منتجات جافة | C10: RM-00206 | D10: Mehran red pepper فلفل أحمر مهران | E10: Box | F10: Box | G10: 1 | H10: =VLOOKUP($C10,'Master File June-26'!$C$3:$L$670,6,0) -> 1 | I10: =VLOOKUP($C10,'Master File June-26'!$C$3:$L$670,7,0) -> 1 | J10: =VLOOKUP($C10,'Master File June-26'!$C$3:$L$670,8,0) -> 14 | K10: =VLOOKUP($C10,'Master File June-26'!$C$3:$L$670,9,0) -> 0.5 | L10: =VLOOKUP($C10,'Master File June-26'!$C$3:$L$670,10,0) -> 0 | M10: =IFERROR((L10/I10*30),0) -> 0 | N10: =IF(M10<J10,"ORDER NOW","IN STOCK") -> ORDER NOW | O10: =IF(M10<J10,"CRITICAL","FOLLOW UP DELIVERY") -> CRITICAL | S10: =IF(L10<K10,0,1) -> 0
A11: 64 | B11: طباعة وتغليف - Packaging | C11: PM-00139 | D11: كرت الاسبريسو نمق (سان اجناسيو) Espresso card (San Ignacio) | E11: 1 Bundle X 500 pcs | F11: bundel | G11: 0.002 | H11: =VLOOKUP($C11,'Master File June-26'!$C$3:$L$670,6,0) -> 5.5 | I11: =VLOOKUP($C11,'Master File June-26'!$C$3:$L$670,7,0) -> 2750 | J11: =VLOOKUP($C11,'Master File June-26'!$C$3:$L$670,8,0) -> 14 | K11: =VLOOKUP($C11,'Master File June-26'!$C$3:$L$670,9,0) -> 1375 | L11: =VLOOKUP($C11,'Master File June-26'!$C$3:$L$670,10,0) -> 0 | M11: =IFERROR((L11/I11*30),0) -> 0 | N11: =IF(M11<J11,"ORDER NOW","IN STOCK") -> ORDER NOW | O11: =IF(M11<J11,"CRITICAL","FOLLOW UP DELIVERY") -> CRITICAL | R11: A | S11: =IF(L11<K11,0,1) -> 0
A12: 651 | C12: RM-00677 | D12: مايونيز قودي / Goody Mayonnaise | E12: Pcs | G12: 1 | H12: =VLOOKUP($C12,'Master File June-26'!$C$3:$L$670,6,0) -> 13 | I12: =VLOOKUP($C12,'Master File June-26'!$C$3:$L$670,7,0) -> 195 | J12: =VLOOKUP($C12,'Master File June-26'!$C$3:$L$670,8,0) -> 14 | K12: =VLOOKUP($C12,'Master File June-26'!$C$3:$L$670,9,0) -> 97.5 | L12: =VLOOKUP($C12,'Master File June-26'!$C$3:$L$670,10,0) -> 211.44 | M12: =IFERROR((L12/I12*30),0) -> 32.529231 | N12: =IF(M12<J12,"ORDER NOW","IN STOCK") -> IN STOCK | O12: =IF(M12<J12,"CRITICAL","FOLLOW UP DELIVERY") -> FOLLOW UP DELIVERY | S12: =IF(L12<K12,0,1) -> 1
A13: 398 | B13: Dry Goods - منتجات جافة | C13: RM-00677 | D13: مايونيز قودي / Goody Mayonnaise | E13: 1 Box X 4 Pcs X 3.75 | F13: Box | G13: =1/15 -> 0.066666667 | H13: =VLOOKUP($C13,'Master File June-26'!$C$3:$L$670,6,0) -> 13 | I13: =VLOOKUP($C13,'Master File June-26'!$C$3:$L$670,7,0) -> 195 | J13: =VLOOKUP($C13,'Master File June-26'!$C$3:$L$670,8,0) -> 14 | K13: =VLOOKUP($C13,'Master File June-26'!$C$3:$L$670,9,0) -> 97.5 | L13: =VLOOKUP($C13,'Master File June-26'!$C$3:$L$670,10,0) -> 211.44 | M13: =IFERROR((L13/I13*30),0) -> 32.529231 | N13: =IF(M13<J13,"ORDER NOW","IN STOCK") -> IN STOCK | O13: =IF(M13<J13,"CRITICAL","FOLLOW UP DELIVERY") -> FOLLOW UP DELIVERY | S13: =IF(L13<K13,0,1) -> 1
A14: 354 | B14: Dry Goods - منتجات جافة | C14: RM-00415 | D14: جوز البيكان | Pecan nuts | E14: 1 Bag X 13.6 Kg | F14: bag | G14: 0.076923077 | H14: =VLOOKUP($C14,'Master File June-26'!$C$3:$L$670,6,0) -> 89.5 | I14: =VLOOKUP($C14,'Master File June-26'!$C$3:$L$670,7,0) -> 1163.5 | J14: =VLOOKUP($C14,'Master File June-26'!$C$3:$L$670,8,0) -> 14 | K14: =VLOOKUP($C14,'Master File June-26'!$C$3:$L$670,9,0) -> 581.75 | L14: =VLOOKUP($C14,'Master File June-26'!$C$3:$L$670,10,0) -> 0 | M14: =IFERROR((L14/I14*30),0) -> 0 | N14: =IF(M14<J14,"ORDER NOW","IN STOCK") -> ORDER NOW | O14: =IF(M14<J14,"CRITICAL","FOLLOW UP DELIVERY") -> CRITICAL | S14: =IF(L14<K14,0,1) -> 0
A15: 516 | B15: Dry Goods - منتجات جافة | C15: RM-00421 | D15: Coconut powder | جوز الهند بودر | E15: 1 BAG X X 7 KG | F15: bag | G15: 0.14285714 | H15: =VLOOKUP($C15,'Master File June-26'!$C$3:$L$670,6,0) -> 43 | I15: =VLOOKUP($C15,'Master File June-26'!$C$3:$L$670,7,0) -> 301 | J15: =VLOOKUP($C15,'Master File June-26'!$C$3:$L$670,8,0) -> 14 | K15: =VLOOKUP($C15,'Master File June-26'!$C$3:$L$670,9,0) -> 150.5 | L15: =VLOOKUP($C15,'Master File June-26'!$C$3:$L$670,10,0) -> 0 | M15: =IFERROR((L15/I15*30),0) -> 0 | N15: =IF(M15<J15,"ORDER NOW","IN STOCK") -> ORDER NOW | O15: =IF(M15<J15,"CRITICAL","FOLLOW UP DELIVERY") -> CRITICAL | S15: =IF(L15<K15,0,1) -> 0
A16: 491 | B16: Dry Goods - منتجات جافة | C16: RM-00183 | D16: Ketchup Tomato كاتشب | E16: 1 Box X 10pcs X 570 grm | F16: Box | G16: 0.1754386 | H16: =VLOOKUP($C16,'Master File June-26'!$C$3:$L$670,6,0) -> 4 | I16: =VLOOKUP($C16,'Master File June-26'!$C$3:$L$670,7,0) -> 22.8 | J16: =VLOOKUP($C16,'Master File June-26'!$C$3:$L$670,8,0) -> 14 | K16: =VLOOKUP($C16,'Master File June-26'!$C$3:$L$670,9,0) -> 11.4 | L16: =VLOOKUP($C16,'Master File June-26'!$C$3:$L$670,10,0) -> 23.94 | M16: =IFERROR((L16/I16*30),0) -> 31.5 | N16: =IF(M16<J16,"ORDER NOW","IN STOCK") -> IN STOCK | O16: =IF(M16<J16,"CRITICAL","FOLLOW UP DELIVERY") -> FOLLOW UP DELIVERY | S16: =IF(L16<K16,0,1) -> 1
A17: 543 | B17: FROZEN ITEMS - منتجات مجمدة | C17: RM-00018 | D17: جبن شيدر انجليزي Irish Mild yellow cheddar Cheese | E17: KG | F17: Pcs | G17: 1 | H17: =VLOOKUP($C17,'Master File June-26'!$C$3:$L$670,6,0) -> 13 | I17: =VLOOKUP($C17,'Master File June-26'!$C$3:$L$670,7,0) -> 13 | J17: =VLOOKUP($C17,'Master File June-26'!$C$3:$L$670,8,0) -> 14 | K17: =VLOOKUP($C17,'Master File June-26'!$C$3:$L$670,9,0) -> 6.5 | L17: =VLOOKUP($C17,'Master File June-26'!$C$3:$L$670,10,0) -> 0 | M17: =IFERROR((L17/I17*30),0) -> 0 | N17: =IF(M17<J17,"ORDER NOW","IN STOCK") -> ORDER NOW | O17: =IF(M17<J17,"CRITICAL","FOLLOW UP DELIVERY") -> CRITICAL | S17: =IF(L17<K17,0,1) -> 0
A18: 390 | B18: Dry Goods - منتجات جافة | C18: RM-00681 | D18: معبوج تمر هندي / Tamrind | E18: 1 Pcs X 500 G | F18: Pcs | G18: 2 | H18: =VLOOKUP($C18,'Master File June-26'!$C$3:$L$670,6,0) -> 44 | I18: =VLOOKUP($C18,'Master File June-26'!$C$3:$L$670,7,0) -> 22 | J18: =VLOOKUP($C18,'Master File June-26'!$C$3:$L$670,8,0) -> 14 | K18: =VLOOKUP($C18,'Master File June-26'!$C$3:$L$670,9,0) -> 11 | L18: =VLOOKUP($C18,'Master File June-26'!$C$3:$L$670,10,0) -> 0 | M18: =IFERROR((L18/I18*30),0) -> 0 | N18: =IF(M18<J18,"ORDER NOW","IN STOCK") -> ORDER NOW | O18: =IF(M18<J18,"CRITICAL","FOLLOW UP DELIVERY") -> CRITICAL | S18: =IF(L18<K18,0,1) -> 0
A19: 495 | B19: Dry Goods - منتجات جافة | C19: RM-00423 | D19: Hazelnut بندق | E19: 1 Bag X 10 Kg | F19: Box | G19: 0.1 | H19: =VLOOKUP($C19,'Master File June-26'!$C$3:$L$670,6,0) -> 120 | I19: =VLOOKUP($C19,'Master File June-26'!$C$3:$L$670,7,0) -> 1200 | J19: =VLOOKUP($C19,'Master File June-26'!$C$3:$L$670,8,0) -> 14 | K19: =VLOOKUP($C19,'Master File June-26'!$C$3:$L$670,9,0) -> 600 | L19: =VLOOKUP($C19,'Master File June-26'!$C$3:$L$670,10,0) -> 0 | M19: =IFERROR((L19/I19*30),0) -> 0 | N19: =IF(M19<J19,"ORDER NOW","IN STOCK") -> ORDER NOW | O19: =IF(M19<J19,"CRITICAL","FOLLOW UP DELIVERY") -> CRITICAL | S19: =IF(L19<K19,0,1) -> 0
A20: 273 | B20: طباعة وتغليف - Packaging | C20: CO-00467 | D20: Glass cup 65ml كوب زجاج 65 ملي لتقديم المياه الغازية | E20: 1 Box X 6 Pcs | F20: Box | G20: 0.16666667 | H20: =VLOOKUP($C20,'Master File June-26'!$C$3:$L$670,6,0) -> 22 | I20: =VLOOKUP($C20,'Master File June-26'!$C$3:$L$670,7,0) -> 132 | J20: =VLOOKUP($C20,'Master File June-26'!$C$3:$L$670,8,0) -> 14 | K20: =VLOOKUP($C20,'Master File June-26'!$C$3:$L$670,9,0) -> 66 | L20: =VLOOKUP($C20,'Master File June-26'!$C$3:$L$670,10,0) -> 36 | M20: =IFERROR((L20/I20*30),0) -> 8.1818182 | N20: =IF(M20<J20,"ORDER NOW","IN STOCK") -> ORDER NOW | O20: =IF(M20<J20,"CRITICAL","FOLLOW UP DELIVERY") -> CRITICAL | S20: =IF(L20<K20,0,1) -> 0
A21: 386 | B21: Dry Goods - منتجات جافة | C21: RM-00439 | D21: Unroasted peanuts | فول سوداني | E21: 1 Bag X 10 Kg | F21: bag | G21: 0.1 | H21: =VLOOKUP($C21,'Master File June-26'!$C$3:$L$670,6,0) -> 9.5 | I21: =VLOOKUP($C21,'Master File June-26'!$C$3:$L$670,7,0) -> 95 | J21: =VLOOKUP($C21,'Master File June-26'!$C$3:$L$670,8,0) -> 14 | K21: =VLOOKUP($C21,'Master File June-26'!$C$3:$L$670,9,0) -> 47.5 | L21: =VLOOKUP($C21,'Master File June-26'!$C$3:$L$670,10,0) -> 20 | M21: =IFERROR((L21/I21*30),0) -> 6.3157895 | N21: =IF(M21<J21,"ORDER NOW","IN STOCK") -> ORDER NOW | O21: =IF(M21<J21,"CRITICAL","FOLLOW UP DELIVERY") -> CRITICAL | S21: =IF(L21<K21,0,1) -> 0
A22: 58 | B22: طباعة وتغليف - Packaging | C22: PM-00528 | D22: كوب فخار 200 مل - محفور بشعار من الداخل والخارج - قليز شفاف مطفي | E22: Pcs. | F22: Pcs | G22: 1 | H22: =VLOOKUP($C22,'Master File June-26'!$C$3:$L$670,6,0) -> 20 | I22: =VLOOKUP($C22,'Master File June-26'!$C$3:$L$670,7,0) -> 20 | J22: =VLOOKUP($C22,'Master File June-26'!$C$3:$L$670,8,0) -> 30 | K22: =VLOOKUP($C22,'Master File June-26'!$C$3:$L$670,9,0) -> 21.428571 | L22: =VLOOKUP($C22,'Master File June-26'!$C$3:$L$670,10,0) -> 0 | M22: =IFERROR((L22/I22*30),0) -> 0 | N22: =IF(M22<J22,"ORDER NOW","IN STOCK") -> ORDER NOW | O22: =IF(M22<J22,"CRITICAL","FOLLOW UP DELIVERY") -> CRITICAL | R22: A | S22: =IF(L22<K22,0,1) -> 0
A23: 380 | B23: Dry Goods - منتجات جافة | C23: RM-00006 | D23: Goody Creamy Peanut Butte | قودي زبدة الفول السوداني الناعمة | E23: 12pcs x 1 kg | F23: Pcs | G23: 0.083333333 | H23: =VLOOKUP($C23,'Master File June-26'!$C$3:$L$670,6,0) -> 55 | I23: =VLOOKUP($C23,'Master File June-26'!$C$3:$L$670,7,0) -> 660 | J23: =VLOOKUP($C23,'Master File June-26'!$C$3:$L$670,8,0) -> 14 | K23: =VLOOKUP($C23,'Master File June-26'!$C$3:$L$670,9,0) -> 330 | L23: =VLOOKUP($C23,'Master File June-26'!$C$3:$L$670,10,0) -> 6.2 | M23: =IFERROR((L23/I23*30),0) -> 0.28181818 | N23: =IF(M23<J23,"ORDER NOW","IN STOCK") -> ORDER NOW | O23: =IF(M23<J23,"CRITICAL","FOLLOW UP DELIVERY") -> CRITICAL | S23: =IF(L23<K23,0,1) -> 0
A24: 395 | B24: Dry Goods - منتجات جافة | C24: RM-00175 | D24: ORIG RANCH SAUCE | صوص الرانش | E24: 1X6X530 GM (3.8 KG) | F24: KG | G24: =1/3.8 -> 0.26315789 | H24: =VLOOKUP($C24,'Master File June-26'!$C$3:$L$670,6,0) -> 16 | I24: =VLOOKUP($C24,'Master File June-26'!$C$3:$L$670,7,0) -> 60.8 | J24: =VLOOKUP($C24,'Master File June-26'!$C$3:$L$670,8,0) -> 14 | K24: =VLOOKUP($C24,'Master File June-26'!$C$3:$L$670,9,0) -> 30.4 | L24: =VLOOKUP($C24,'Master File June-26'!$C$3:$L$670,10,0) -> 0 | M24: =IFERROR((L24/I24*30),0) -> 0 | N24: =IF(M24<J24,"ORDER NOW","IN STOCK") -> ORDER NOW | O24: =IF(M24<J24,"CRITICAL","FOLLOW UP DELIVERY") -> CRITICAL | S24: =IF(L24<K24,0,1) -> 0
A25: 343 | B25: Beverage - مشروبات | C25: RM-00320 | D25: صوص جوز البيكان VARIEGATO NOCE PECAN | E25: 1 Ctn. X 2 Tin X 5kg | F25: Ctn | G25: 0.1 | H25: =VLOOKUP($C25,'Master File June-26'!$C$3:$L$670,6,0) -> 143 | I25: =VLOOKUP($C25,'Master File June-26'!$C$3:$L$670,7,0) -> 1430 | J25: =VLOOKUP($C25,'Master File June-26'!$C$3:$L$670,8,0) -> 14 | K25: =VLOOKUP($C25,'Master File June-26'!$C$3:$L$670,9,0) -> 715 | L25: =VLOOKUP($C25,'Master File June-26'!$C$3:$L$670,10,0) -> 650 | M25: =IFERROR((L25/I25*30),0) -> 13.636364 | N25: =IF(M25<J25,"ORDER NOW","IN STOCK") -> ORDER NOW | O25: =IF(M25<J25,"CRITICAL","FOLLOW UP DELIVERY") -> CRITICAL | S25: =IF(L25<K25,0,1) -> 0
A26: 22 | B26: طباعة وتغليف - Packaging | C26: PM-00251 | D26: 4 Oz Sauce Cup plasticعلبة صوص 4 اونصه بلاستيك | E26: 1 Box X 20 Pack X 100 Pcs | F26: Box | G26: 0.0005 | H26: =VLOOKUP($C26,'Master File June-26'!$C$3:$L$670,6,0) -> 145.5 | I26: =VLOOKUP($C26,'Master File June-26'!$C$3:$L$670,7,0) -> 291000 | J26: =VLOOKUP($C26,'Master File June-26'!$C$3:$L$670,8,0) -> 14 | K26: =VLOOKUP($C26,'Master File June-26'!$C$3:$L$670,9,0) -> 145500 | L26: =VLOOKUP($C26,'Master File June-26'!$C$3:$L$670,10,0) -> 65500 | M26: =IFERROR((L26/I26*30),0) -> 6.7525773 | N26: =IF(M26<J26,"ORDER NOW","IN STOCK") -> ORDER NOW | O26: =IF(M26<J26,"CRITICAL","FOLLOW UP DELIVERY") -> CRITICAL | R26: A | S26: =IF(L26<K26,0,1) -> 0
A27: 70 | B27: طباعة وتغليف - Packaging | C27: PM-00261 | D27: Baking Paper 60*40 ورق خبازة 60*40 | E27: 1 Box X 500 Pcs. / 1 Box X 1000 Pcs. | F27: Box | G27: 0.002 | H27: =VLOOKUP($C27,'Master File June-26'!$C$3:$L$670,6,0) -> 100 | I27: =VLOOKUP($C27,'Master File June-26'!$C$3:$L$670,7,0) -> 50000 | J27: =VLOOKUP($C27,'Master File June-26'!$C$3:$L$670,8,0) -> 14 | K27: =VLOOKUP($C27,'Master File June-26'!$C$3:$L$670,9,0) -> 25000 | L27: =VLOOKUP($C27,'Master File June-26'!$C$3:$L$670,10,0) -> 44000 | M27: =IFERROR((L27/I27*30),0) -> 26.4 | N27: =IF(M27<J27,"ORDER NOW","IN STOCK") -> IN STOCK | O27: =IF(M27<J27,"CRITICAL","FOLLOW UP DELIVERY") -> FOLLOW UP DELIVERY | R27: A | S27: =IF(L27<K27,0,1) -> 1
A28: 102 | B28: طباعة وتغليف - Packaging | C28: PM-00357 | D28: Pomegranate Iced Tea Sticker ( breehant ) ستيكر شاي مثلج بالرمان (بريهانت) | E28: 1 bundle X 500 PCS | F28: bundel | G28: 0.002 | H28: =VLOOKUP($C28,'Master File June-26'!$C$3:$L$670,6,0) -> 16 | I28: =VLOOKUP($C28,'Master File June-26'!$C$3:$L$670,7,0) -> 8000 | J28: =VLOOKUP($C28,'Master File June-26'!$C$3:$L$670,8,0) -> 14 | K28: =VLOOKUP($C28,'Master File June-26'!$C$3:$L$670,9,0) -> 4000 | L28: =VLOOKUP($C28,'Master File June-26'!$C$3:$L$670,10,0) -> 3000 | M28: =IFERROR((L28/I28*30),0) -> 11.25 | N28: =IF(M28<J28,"ORDER NOW","IN STOCK") -> ORDER NOW | O28: =IF(M28<J28,"CRITICAL","FOLLOW UP DELIVERY") -> CRITICAL | R28: A | S28: =IF(L28<K28,0,1) -> 0
A29: 602 | B29: Beverage - مشروبات | C29: SF-00154 | D29: Monin PEACH TEA Syrup 1L مونین شراب شاي الخوخ 1لتر | E29: 1 Box X 6 Bottle X 1 Ltr | F29: Box | G29: =1/6 -> 0.16666667 | H29: =VLOOKUP($C29,'Master File June-26'!$C$3:$L$670,6,0) -> 5.5 | I29: =VLOOKUP($C29,'Master File June-26'!$C$3:$L$670,7,0) -> 33 | J29: =VLOOKUP($C29,'Master File June-26'!$C$3:$L$670,8,0) -> 14 | K29: =VLOOKUP($C29,'Master File June-26'!$C$3:$L$670,9,0) -> 16.5 | L29: =VLOOKUP($C29,'Master File June-26'!$C$3:$L$670,10,0) -> 0 | M29: =IFERROR((L29/I29*30),0) -> 0 | N29: =IF(M29<J29,"ORDER NOW","IN STOCK") -> ORDER NOW | O29: =IF(M29<J29,"CRITICAL","FOLLOW UP DELIVERY") -> CRITICAL | S29: =IF(L29<K29,0,1) -> 0
A30: 358 | B30: Beverage - مشروبات | C30: RM-00582 | D30: Syrup Mango Teisseireسيروب المانجو | E30: 1 Box X 6 Bottle X 1 Ltr | F30: Box | G30: 0.16666667 | H30: =VLOOKUP($C30,'Master File June-26'!$C$3:$L$670,6,0) -> 5.5 | I30: =VLOOKUP($C30,'Master File June-26'!$C$3:$L$670,7,0) -> 33 | J30: =VLOOKUP($C30,'Master File June-26'!$C$3:$L$670,8,0) -> 14 | K30: =VLOOKUP($C30,'Master File June-26'!$C$3:$L$670,9,0) -> 16.5 | L30: =VLOOKUP($C30,'Master File June-26'!$C$3:$L$670,10,0) -> 0 | M30: =IFERROR((L30/I30*30),0) -> 0 | N30: =IF(M30<J30,"ORDER NOW","IN STOCK") -> ORDER NOW | O30: =IF(M30<J30,"CRITICAL","FOLLOW UP DELIVERY") -> CRITICAL | S30: =IF(L30<K30,0,1) -> 0
A31: 401 | B31: Beverage - مشروبات / Dairy | C31: RM-00508 | D31: Condensed milkحليب مكثف | E31: 1 Box X 24 Pcs. X 1 Kilo | F31: Box | G31: 0.041666667 | H31: =VLOOKUP($C31,'Master File June-26'!$C$3:$L$670,6,0) -> 56 | I31: =VLOOKUP($C31,'Master File June-26'!$C$3:$L$670,7,0) -> 1344 | J31: =VLOOKUP($C31,'Master File June-26'!$C$3:$L$670,8,0) -> 14 | K31: =VLOOKUP($C31,'Master File June-26'!$C$3:$L$670,9,0) -> 672 | L31: =VLOOKUP($C31,'Master File June-26'!$C$3:$L$670,10,0) -> 5884.8 | M31: =IFERROR((L31/I31*30),0) -> 131.35714 | N31: =IF(M31<J31,"ORDER NOW","IN STOCK") -> IN STOCK | O31: =IF(M31<J31,"CRITICAL","FOLLOW UP DELIVERY") -> FOLLOW UP DELIVERY | S31: =IF(L31<K31,0,1) -> 1
A32: 599 | B32: Beverage - مشروبات / Dairy | C32: SF-00189 | D32: MANGO RIPPLING SAUSE - صوص المانجو مع القطع | E32: 1 Box X 2Ltr | F32: Box | G32: 0.5 | H32: =VLOOKUP($C32,'Master File June-26'!$C$3:$L$670,6,0) -> 38.5 | I32: =VLOOKUP($C32,'Master File June-26'!$C$3:$L$670,7,0) -> 77 | J32: =VLOOKUP($C32,'Master File June-26'!$C$3:$L$670,8,0) -> 14 | K32: =VLOOKUP($C32,'Master File June-26'!$C$3:$L$670,9,0) -> 38.5 | L32: =VLOOKUP($C32,'Master File June-26'!$C$3:$L$670,10,0) -> 0 | M32: =IFERROR((L32/I32*30),0) -> 0 | N32: =IF(M32<J32,"ORDER NOW","IN STOCK") -> ORDER NOW | O32: =IF(M32<J32,"CRITICAL","FOLLOW UP DELIVERY") -> CRITICAL | S32: =IF(L32<K32,0,1) -> 0
A33: 385 | B33: Beverage - مشروبات | C33: RM-00445 | D33: Kompletin Spray Oil بخاخ زيت كومبليت ان | E33: 1 Box X 6 Pcs X 500ml | F33: Box | G33: 0.33333333 | H33: =VLOOKUP($C33,'Master File June-26'!$C$3:$L$670,6,0) -> 135 | I33: =VLOOKUP($C33,'Master File June-26'!$C$3:$L$670,7,0) -> 405 | J33: =VLOOKUP($C33,'Master File June-26'!$C$3:$L$670,8,0) -> 14 | K33: =VLOOKUP($C33,'Master File June-26'!$C$3:$L$670,9,0) -> 202.5 | L33: =VLOOKUP($C33,'Master File June-26'!$C$3:$L$670,10,0) -> 1050 | M33: =IFERROR((L33/I33*30),0) -> 77.777778 | N33: =IF(M33<J33,"ORDER NOW","IN STOCK") -> IN STOCK | O33: =IF(M33<J33,"CRITICAL","FOLLOW UP DELIVERY") -> FOLLOW UP DELIVERY | S33: =IF(L33<K33,0,1) -> 1
A34: 356 | B34: Dry Goods - منتجات جافة | C34: RM-00432 | D34: Sliced almond لوز شرايح امريكي | E34: 1 Box X 10 Kg | F34: Box | G34: 0.1 | H34: =VLOOKUP($C34,'Master File June-26'!$C$3:$L$670,6,0) -> 19 | I34: =VLOOKUP($C34,'Master File June-26'!$C$3:$L$670,7,0) -> 190 | J34: =VLOOKUP($C34,'Master File June-26'!$C$3:$L$670,8,0) -> 14 | K34: =VLOOKUP($C34,'Master File June-26'!$C$3:$L$670,9,0) -> 95 | L34: =VLOOKUP($C34,'Master File June-26'!$C$3:$L$670,10,0) -> 0 | M34: =IFERROR((L34/I34*30),0) -> 0 | N34: =IF(M34<J34,"ORDER NOW","IN STOCK") -> ORDER NOW | O34: =IF(M34<J34,"CRITICAL","FOLLOW UP DELIVERY") -> CRITICAL | S34: =IF(L34<K34,0,1) -> 0
A35: 97 | B35: طباعة وتغليف - Packaging | C35: PM-00270 | D35: lids Cups Brehehant with stick اغطية اكواب القهوة - بريهانت | E35: 1 Box X 20 Pack X 50 Pcs | F35: Box | G35: 0.001 | H35: =VLOOKUP($C35,'Master File June-26'!$C$3:$L$670,6,0) -> 400 | I35: =VLOOKUP($C35,'Master File June-26'!$C$3:$L$670,7,0) -> 400000 | J35: =VLOOKUP($C35,'Master File June-26'!$C$3:$L$670,8,0) -> 14 | K35: =VLOOKUP($C35,'Master File June-26'!$C$3:$L$670,9,0) -> 200000 | L35: =VLOOKUP($C35,'Master File June-26'!$C$3:$L$670,10,0) -> 0 | M35: =IFERROR((L35/I35*30),0) -> 0 | N35: =IF(M35<J35,"ORDER NOW","IN STOCK") -> ORDER NOW | O35: =IF(M35<J35,"CRITICAL","FOLLOW UP DELIVERY") -> CRITICAL | R35: A | S35: =IF(L35<K35,0,1) -> 0
A36: 384 | B36: Dry Goods - منتجات جافة | C36: RM-00673 | D36: Valrhona Javira 40% / شوكولاته فالرهونا | E36: 1 Box X 3 x 3 KG | F36: Box | G36: =1/9 -> 0.11111111 | H36: =VLOOKUP($C36,'Master File June-26'!$C$3:$L$670,6,0) -> 22 | I36: =VLOOKUP($C36,'Master File June-26'!$C$3:$L$670,7,0) -> 198 | J36: =VLOOKUP($C36,'Master File June-26'!$C$3:$L$670,8,0) -> 14 | K36: =VLOOKUP($C36,'Master File June-26'!$C$3:$L$670,9,0) -> 99 | L36: =VLOOKUP($C36,'Master File June-26'!$C$3:$L$670,10,0) -> 0 | M36: =IFERROR((L36/I36*30),0) -> 0 | N36: =IF(M36<J36,"ORDER NOW","IN STOCK") -> ORDER NOW | O36: =IF(M36<J36,"CRITICAL","FOLLOW UP DELIVERY") -> CRITICAL | S36: =IF(L36<K36,0,1) -> 0
A37: 215 | B37: Cleaning - منظفات | C37: CO-00061 | D37: Steam cleaner 1 liter منظف الاستيم 1 لتر | E37: 1 Pcs. X 1 Ltr | F37: Pcs | G37: 1 | H37: =VLOOKUP($C37,'Master File June-26'!$C$3:$L$670,6,0) -> 233 | I37: =VLOOKUP($C37,'Master File June-26'!$C$3:$L$670,7,0) -> 233 | J37: =VLOOKUP($C37,'Master File June-26'!$C$3:$L$670,8,0) -> 14 | K37: =VLOOKUP($C37,'Master File June-26'!$C$3:$L$670,9,0) -> 116.5 | L37: =VLOOKUP($C37,'Master File June-26'!$C$3:$L$670,10,0) -> 38 | M37: =IFERROR((L37/I37*30),0) -> 4.8927039 | N37: =IF(M37<J37,"ORDER NOW","IN STOCK") -> ORDER NOW | O37: =IF(M37<J37,"CRITICAL","FOLLOW UP DELIVERY") -> CRITICAL | S37: =IF(L37<K37,0,1) -> 0
A38: 375 | B38: Beverage - مشروبات | C38: RM-00538 | D38: SYRUP LEMONADE 1883 سيروب ليموناضة | E38: 1 Box X 6 Bottle X 1 Ltr | F38: Box | G38: 0.16666667 | H38: =VLOOKUP($C38,'Master File June-26'!$C$3:$L$670,6,0) -> 16.5 | I38: =VLOOKUP($C38,'Master File June-26'!$C$3:$L$670,7,0) -> 99 | J38: =VLOOKUP($C38,'Master File June-26'!$C$3:$L$670,8,0) -> 14 | K38: =VLOOKUP($C38,'Master File June-26'!$C$3:$L$670,9,0) -> 49.5 | L38: =VLOOKUP($C38,'Master File June-26'!$C$3:$L$670,10,0) -> 99 | M38: =IFERROR((L38/I38*30),0) -> 30 | N38: =IF(M38<J38,"ORDER NOW","IN STOCK") -> IN STOCK | O38: =IF(M38<J38,"CRITICAL","FOLLOW UP DELIVERY") -> FOLLOW UP DELIVERY | S38: =IF(L38<K38,0,1) -> 1
A39: 96 | B39: طباعة وتغليف - Packaging | C39: PM-00287 | D39: lids Cups Brehehant 6.5 Oz 80 ml اغطية اكواب القهوة - بريهانت 6.5 اونصه | E39: 1 Box X 20 Pack X 50 Pcs | F39: Box | G39: 0.001 | H39: =VLOOKUP($C39,'Master File June-26'!$C$3:$L$670,6,0) -> 18 | I39: =VLOOKUP($C39,'Master File June-26'!$C$3:$L$670,7,0) -> 18000 | J39: =VLOOKUP($C39,'Master File June-26'!$C$3:$L$670,8,0) -> 14 | K39: =VLOOKUP($C39,'Master File June-26'!$C$3:$L$670,9,0) -> 9000 | L39: =VLOOKUP($C39,'Master File June-26'!$C$3:$L$670,10,0) -> 0 | M39: =IFERROR((L39/I39*30),0) -> 0 | N39: =IF(M39<J39,"ORDER NOW","IN STOCK") -> ORDER NOW | O39: =IF(M39<J39,"CRITICAL","FOLLOW UP DELIVERY") -> CRITICAL | R39: A | S39: =IF(L39<K39,0,1) -> 0
A40: 494 | B40: Dry Goods - منتجات جافة | C40: RM-00434 | D40: Walnuts عين جمل | E40: 1 Box X 10 Kg | F40: Box | G40: 0.1 | H40: =VLOOKUP($C40,'Master File June-26'!$C$3:$L$670,6,0) -> 200 | I40: =VLOOKUP($C40,'Master File June-26'!$C$3:$L$670,7,0) -> 2000 | J40: =VLOOKUP($C40,'Master File June-26'!$C$3:$L$670,8,0) -> 14 | K40: =VLOOKUP($C40,'Master File June-26'!$C$3:$L$670,9,0) -> 1000 | L40: =VLOOKUP($C40,'Master File June-26'!$C$3:$L$670,10,0) -> 0 | M40: =IFERROR((L40/I40*30),0) -> 0 | N40: =IF(M40<J40,"ORDER NOW","IN STOCK") -> ORDER NOW | O40: =IF(M40<J40,"CRITICAL","FOLLOW UP DELIVERY") -> CRITICAL | S40: =IF(L40<K40,0,1) -> 0
...

Sheet Raw Material Stock status
A2: Item Code | B2: Item Description | C2: Packing | D2: UOM | E2: Conversion | F2: QTY in Pack | G2: QTY in Unit | H2: Lead Time | I2: Reordering Point | J2: WH Stocks | K2: Coverage/Day | L2: 0rder Status | M2: Criticality | N2: Stock Status
A3: RM-00502 | B3: Sugar Jaggery Vijay سكر جاجيري مدور | C3: Box | D3: Box | E3: 1 | F3: =VLOOKUP($A3,'Master File June-26'!$C$3:$L$670,6,0) -> 2 | G3: =VLOOKUP($A3,'Master File June-26'!$C$3:$L$670,7,0) -> 2 | H3: =VLOOKUP($A3,'Master File June-26'!$C$3:$L$670,8,0) -> 14 | I3: =VLOOKUP($A3,'Master File June-26'!$C$3:$L$670,9,0) -> 1 | J3: =VLOOKUP($A3,'Master File June-26'!$C$3:$L$670,10,0) -> 0 | K3: =IFERROR((J3/G3*30),0) -> 0 | L3: =IF(K3<H3,"ORDER NOW","IN STOCK") -> ORDER NOW | M3: =IF(K3<H3,"CRITICAL","FOLLOW UP DELIVERY") -> CRITICAL | N3: 1
A4: RM-00206 | B4: Mehran red pepper فلفل أحمر مهران | C4: Box | D4: Box | E4: 1 | F4: =VLOOKUP($A4,'Master File June-26'!$C$3:$L$670,6,0) -> 1 | G4: =VLOOKUP($A4,'Master File June-26'!$C$3:$L$670,7,0) -> 1 | H4: =VLOOKUP($A4,'Master File June-26'!$C$3:$L$670,8,0) -> 14 | I4: =VLOOKUP($A4,'Master File June-26'!$C$3:$L$670,9,0) -> 0.5 | J4: =VLOOKUP($A4,'Master File June-26'!$C$3:$L$670,10,0) -> 0 | K4: =IFERROR((J4/G4*30),0) -> 0 | L4: =IF(K4<H4,"ORDER NOW","IN STOCK") -> ORDER NOW | M4: =IF(K4<H4,"CRITICAL","FOLLOW UP DELIVERY") -> CRITICAL | N4: 1
A5: RM-00677 | B5: مايونيز قودي / Goody Mayonnaise | C5: 1 Box X 4 Pcs X 3.75 | D5: Box | E5: 0.066666667 | F5: =VLOOKUP($A5,'Master File June-26'!$C$3:$L$670,6,0) -> 13 | G5: =VLOOKUP($A5,'Master File June-26'!$C$3:$L$670,7,0) -> 195 | H5: =VLOOKUP($A5,'Master File June-26'!$C$3:$L$670,8,0) -> 14 | I5: =VLOOKUP($A5,'Master File June-26'!$C$3:$L$670,9,0) -> 97.5 | J5: =VLOOKUP($A5,'Master File June-26'!$C$3:$L$670,10,0) -> 211.44 | K5: =IFERROR((J5/G5*30),0) -> 32.529231 | L5: =IF(K5<H5,"ORDER NOW","IN STOCK") -> IN STOCK | M5: =IF(K5<H5,"CRITICAL","FOLLOW UP DELIVERY") -> FOLLOW UP DELIVERY | N5: 1
A6: RM-00415 | B6: جوز البيكان | Pecan nuts | C6: 1 Bag X 13.6 Kg | D6: bag | E6: 0.076923077 | F6: =VLOOKUP($A6,'Master File June-26'!$C$3:$L$670,6,0) -> 89.5 | G6: =VLOOKUP($A6,'Master File June-26'!$C$3:$L$670,7,0) -> 1163.5 | H6: =VLOOKUP($A6,'Master File June-26'!$C$3:$L$670,8,0) -> 14 | I6: =VLOOKUP($A6,'Master File June-26'!$C$3:$L$670,9,0) -> 581.75 | J6: =VLOOKUP($A6,'Master File June-26'!$C$3:$L$670,10,0) -> 0 | K6: =IFERROR((J6/G6*30),0) -> 0 | L6: =IF(K6<H6,"ORDER NOW","IN STOCK") -> ORDER NOW | M6: =IF(K6<H6,"CRITICAL","FOLLOW UP DELIVERY") -> CRITICAL | N6: 0
A7: RM-00421 | B7: Coconut powder | جوز الهند بودر | C7: 1 BAG X X 7 KG | D7: bag | E7: 0.14285714 | F7: =VLOOKUP($A7,'Master File June-26'!$C$3:$L$670,6,0) -> 43 | G7: =VLOOKUP($A7,'Master File June-26'!$C$3:$L$670,7,0) -> 301 | H7: =VLOOKUP($A7,'Master File June-26'!$C$3:$L$670,8,0) -> 14 | I7: =VLOOKUP($A7,'Master File June-26'!$C$3:$L$670,9,0) -> 150.5 | J7: =VLOOKUP($A7,'Master File June-26'!$C$3:$L$670,10,0) -> 0 | K7: =IFERROR((J7/G7*30),0) -> 0 | L7: =IF(K7<H7,"ORDER NOW","IN STOCK") -> ORDER NOW | M7: =IF(K7<H7,"CRITICAL","FOLLOW UP DELIVERY") -> CRITICAL | N7: 0
A8: RM-00183 | B8: Ketchup Tomato كاتشب | C8: 1 Box X 10pcs X 570 grm | D8: Box | E8: 0.1754386 | F8: =VLOOKUP($A8,'Master File June-26'!$C$3:$L$670,6,0) -> 4 | G8: =VLOOKUP($A8,'Master File June-26'!$C$3:$L$670,7,0) -> 22.8 | H8: =VLOOKUP($A8,'Master File June-26'!$C$3:$L$670,8,0) -> 14 | I8: =VLOOKUP($A8,'Master File June-26'!$C$3:$L$670,9,0) -> 11.4 | J8: =VLOOKUP($A8,'Master File June-26'!$C$3:$L$670,10,0) -> 23.94 | K8: =IFERROR((J8/G8*30),0) -> 31.5 | L8: =IF(K8<H8,"ORDER NOW","IN STOCK") -> IN STOCK | M8: =IF(K8<H8,"CRITICAL","FOLLOW UP DELIVERY") -> FOLLOW UP DELIVERY | N8: 0
A9: RM-00018 | B9: جبن شيدر انجليزي Irish Mild yellow cheddar Cheese | C9: KG | D9: Pcs | E9: 1 | F9: =VLOOKUP($A9,'Master File June-26'!$C$3:$L$670,6,0) -> 13 | G9: =VLOOKUP($A9,'Master File June-26'!$C$3:$L$670,7,0) -> 13 | H9: =VLOOKUP($A9,'Master File June-26'!$C$3:$L$670,8,0) -> 14 | I9: =VLOOKUP($A9,'Master File June-26'!$C$3:$L$670,9,0) -> 6.5 | J9: =VLOOKUP($A9,'Master File June-26'!$C$3:$L$670,10,0) -> 0 | K9: =IFERROR((J9/G9*30),0) -> 0 | L9: =IF(K9<H9,"ORDER NOW","IN STOCK") -> ORDER NOW | M9: =IF(K9<H9,"CRITICAL","FOLLOW UP DELIVERY") -> CRITICAL | N9: 0
A10: RM-00681 | B10: معبوج تمر هندي / Tamrind | C10: 1 Pcs X 500 G | D10: Pcs | E10: 2 | F10: =VLOOKUP($A10,'Master File June-26'!$C$3:$L$670,6,0) -> 44 | G10: =VLOOKUP($A10,'Master File June-26'!$C$3:$L$670,7,0) -> 22 | H10: =VLOOKUP($A10,'Master File June-26'!$C$3:$L$670,8,0) -> 14 | I10: =VLOOKUP($A10,'Master File June-26'!$C$3:$L$670,9,0) -> 11 | J10: =VLOOKUP($A10,'Master File June-26'!$C$3:$L$670,10,0) -> 0 | K10: =IFERROR((J10/G10*30),0) -> 0 | L10: =IF(K10<H10,"ORDER NOW","IN STOCK") -> ORDER NOW | M10: =IF(K10<H10,"CRITICAL","FOLLOW UP DELIVERY") -> CRITICAL | N10: 0
A11: RM-00423 | B11: Hazelnut بندق | C11: 1 Bag X 10 Kg | D11: Box | E11: 0.1 | F11: =VLOOKUP($A11,'Master File June-26'!$C$3:$L$670,6,0) -> 120 | G11: =VLOOKUP($A11,'Master File June-26'!$C$3:$L$670,7,0) -> 1200 | H11: =VLOOKUP($A11,'Master File June-26'!$C$3:$L$670,8,0) -> 14 | I11: =VLOOKUP($A11,'Master File June-26'!$C$3:$L$670,9,0) -> 600 | J11: =VLOOKUP($A11,'Master File June-26'!$C$3:$L$670,10,0) -> 0 | K11: =IFERROR((J11/G11*30),0) -> 0 | L11: =IF(K11<H11,"ORDER NOW","IN STOCK") -> ORDER NOW | M11: =IF(K11<H11,"CRITICAL","FOLLOW UP DELIVERY") -> CRITICAL | N11: 0
A12: RM-00439 | B12: Unroasted peanuts | فول سوداني | C12: 1 Bag X 10 Kg | D12: bag | E12: 0.1 | F12: =VLOOKUP($A12,'Master File June-26'!$C$3:$L$670,6,0) -> 9.5 | G12: =VLOOKUP($A12,'Master File June-26'!$C$3:$L$670,7,0) -> 95 | H12: =VLOOKUP($A12,'Master File June-26'!$C$3:$L$670,8,0) -> 14 | I12: =VLOOKUP($A12,'Master File June-26'!$C$3:$L$670,9,0) -> 47.5 | J12: =VLOOKUP($A12,'Master File June-26'!$C$3:$L$670,10,0) -> 20 | K12: =IFERROR((J12/G12*30),0) -> 6.3157895 | L12: =IF(K12<H12,"ORDER NOW","IN STOCK") -> ORDER NOW | M12: =IF(K12<H12,"CRITICAL","FOLLOW UP DELIVERY") -> CRITICAL | N12: 1
A13: RM-00006 | B13: Goody Creamy Peanut Butte | قودي زبدة الفول السوداني الناعمة | C13: 12pcs x 1 kg | D13: Pcs | E13: 0.083333333 | F13: =VLOOKUP($A13,'Master File June-26'!$C$3:$L$670,6,0) -> 55 | G13: =VLOOKUP($A13,'Master File June-26'!$C$3:$L$670,7,0) -> 660 | H13: =VLOOKUP($A13,'Master File June-26'!$C$3:$L$670,8,0) -> 14 | I13: =VLOOKUP($A13,'Master File June-26'!$C$3:$L$670,9,0) -> 330 | J13: =VLOOKUP($A13,'Master File June-26'!$C$3:$L$670,10,0) -> 6.2 | K13: =IFERROR((J13/G13*30),0) -> 0.28181818 | L13: =IF(K13<H13,"ORDER NOW","IN STOCK") -> ORDER NOW | M13: =IF(K13<H13,"CRITICAL","FOLLOW UP DELIVERY") -> CRITICAL | N13: 0
A14: RM-00175 | B14: ORIG RANCH SAUCE | صوص الرانش | C14: 1X6X530 GM (3.8 KG) | D14: KG | E14: 0.26315789 | F14: =VLOOKUP($A14,'Master File June-26'!$C$3:$L$670,6,0) -> 16 | G14: =VLOOKUP($A14,'Master File June-26'!$C$3:$L$670,7,0) -> 60.8 | H14: =VLOOKUP($A14,'Master File June-26'!$C$3:$L$670,8,0) -> 14 | I14: =VLOOKUP($A14,'Master File June-26'!$C$3:$L$670,9,0) -> 30.4 | J14: =VLOOKUP($A14,'Master File June-26'!$C$3:$L$670,10,0) -> 0 | K14: =IFERROR((J14/G14*30),0) -> 0 | L14: =IF(K14<H14,"ORDER NOW","IN STOCK") -> ORDER NOW | M14: =IF(K14<H14,"CRITICAL","FOLLOW UP DELIVERY") -> CRITICAL | N14: 0
A15: RM-00320 | B15: صوص جوز البيكان VARIEGATO NOCE PECAN | C15: 1 Ctn. X 2 Tin X 5kg | D15: Ctn | E15: 0.1 | F15: =VLOOKUP($A15,'Master File June-26'!$C$3:$L$670,6,0) -> 143 | G15: =VLOOKUP($A15,'Master File June-26'!$C$3:$L$670,7,0) -> 1430 | H15: =VLOOKUP($A15,'Master File June-26'!$C$3:$L$670,8,0) -> 14 | I15: =VLOOKUP($A15,'Master File June-26'!$C$3:$L$670,9,0) -> 715 | J15: =VLOOKUP($A15,'Master File June-26'!$C$3:$L$670,10,0) -> 650 | K15: =IFERROR((J15/G15*30),0) -> 13.636364 | L15: =IF(K15<H15,"ORDER NOW","IN STOCK") -> ORDER NOW | M15: =IF(K15<H15,"CRITICAL","FOLLOW UP DELIVERY") -> CRITICAL | N15: 0
A16: RM-00582 | B16: Syrup Mango Teisseireسيروب المانجو | C16: 1 Box X 6 Bottle X 1 Ltr | D16: Box | E16: 0.16666667 | F16: =VLOOKUP($A16,'Master File June-26'!$C$3:$L$670,6,0) -> 5.5 | G16: =VLOOKUP($A16,'Master File June-26'!$C$3:$L$670,7,0) -> 33 | H16: =VLOOKUP($A16,'Master File June-26'!$C$3:$L$670,8,0) -> 14 | I16: =VLOOKUP($A16,'Master File June-26'!$C$3:$L$670,9,0) -> 16.5 | J16: =VLOOKUP($A16,'Master File June-26'!$C$3:$L$670,10,0) -> 0 | K16: =IFERROR((J16/G16*30),0) -> 0 | L16: =IF(K16<H16,"ORDER NOW","IN STOCK") -> ORDER NOW | M16: =IF(K16<H16,"CRITICAL","FOLLOW UP DELIVERY") -> CRITICAL | N16: 0 | O16: NO Demand
A17: RM-00508 | B17: Condensed milkحليب مكثف | C17: 1 Box X 24 Pcs. X 1 Kilo | D17: Box | E17: 0.041666667 | F17: =VLOOKUP($A17,'Master File June-26'!$C$3:$L$670,6,0) -> 56 | G17: =VLOOKUP($A17,'Master File June-26'!$C$3:$L$670,7,0) -> 1344 | H17: =VLOOKUP($A17,'Master File June-26'!$C$3:$L$670,8,0) -> 14 | I17: =VLOOKUP($A17,'Master File June-26'!$C$3:$L$670,9,0) -> 672 | J17: =VLOOKUP($A17,'Master File June-26'!$C$3:$L$670,10,0) -> 5884.8 | K17: =IFERROR((J17/G17*30),0) -> 131.35714 | L17: =IF(K17<H17,"ORDER NOW","IN STOCK") -> IN STOCK | M17: =IF(K17<H17,"CRITICAL","FOLLOW UP DELIVERY") -> FOLLOW UP DELIVERY | N17: 0
A18: RM-00445 | B18: Kompletin Spray Oil بخاخ زيت كومبليت ان | C18: 1 Box X 6 Pcs X 500ml | D18: Box | E18: 0.33333333 | F18: =VLOOKUP($A18,'Master File June-26'!$C$3:$L$670,6,0) -> 135 | G18: =VLOOKUP($A18,'Master File June-26'!$C$3:$L$670,7,0) -> 405 | H18: =VLOOKUP($A18,'Master File June-26'!$C$3:$L$670,8,0) -> 14 | I18: =VLOOKUP($A18,'Master File June-26'!$C$3:$L$670,9,0) -> 202.5 | J18: =VLOOKUP($A18,'Master File June-26'!$C$3:$L$670,10,0) -> 1050 | K18: =IFERROR((J18/G18*30),0) -> 77.777778 | L18: =IF(K18<H18,"ORDER NOW","IN STOCK") -> IN STOCK | M18: =IF(K18<H18,"CRITICAL","FOLLOW UP DELIVERY") -> FOLLOW UP DELIVERY | N18: 0
A19: RM-00432 | B19: Sliced almond لوز شرايح امريكي | C19: 1 Box X 10 Kg | D19: Box | E19: 0.1 | F19: =VLOOKUP($A19,'Master File June-26'!$C$3:$L$670,6,0) -> 19 | G19: =VLOOKUP($A19,'Master File June-26'!$C$3:$L$670,7,0) -> 190 | H19: =VLOOKUP($A19,'Master File June-26'!$C$3:$L$670,8,0) -> 14 | I19: =VLOOKUP($A19,'Master File June-26'!$C$3:$L$670,9,0) -> 95 | J19: =VLOOKUP($A19,'Master File June-26'!$C$3:$L$670,10,0) -> 0 | K19: =IFERROR((J19/G19*30),0) -> 0 | L19: =IF(K19<H19,"ORDER NOW","IN STOCK") -> ORDER NOW | M19: =IF(K19<H19,"CRITICAL","FOLLOW UP DELIVERY") -> CRITICAL | N19: 1
A20: RM-00673 | B20: Valrhona Javira 40% / شوكولاته فالرهونا | C20: 1 Box X 3 x 3 KG | D20: Box | E20: 0.11111111 | F20: =VLOOKUP($A20,'Master File June-26'!$C$3:$L$670,6,0) -> 22 | G20: =VLOOKUP($A20,'Master File June-26'!$C$3:$L$670,7,0) -> 198 | H20: =VLOOKUP($A20,'Master File June-26'!$C$3:$L$670,8,0) -> 14 | I20: =VLOOKUP($A20,'Master File June-26'!$C$3:$L$670,9,0) -> 99 | J20: =VLOOKUP($A20,'Master File June-26'!$C$3:$L$670,10,0) -> 0 | K20: =IFERROR((J20/G20*30),0) -> 0 | L20: =IF(K20<H20,"ORDER NOW","IN STOCK") -> ORDER NOW | M20: =IF(K20<H20,"CRITICAL","FOLLOW UP DELIVERY") -> CRITICAL | N20: 0 | O20: NO Demand
A21: RM-00538 | B21: SYRUP LEMONADE 1883 سيروب ليموناضة | C21: 1 Box X 6 Bottle X 1 Ltr | D21: Box | E21: 0.16666667 | F21: =VLOOKUP($A21,'Master File June-26'!$C$3:$L$670,6,0) -> 16.5 | G21: =VLOOKUP($A21,'Master File June-26'!$C$3:$L$670,7,0) -> 99 | H21: =VLOOKUP($A21,'Master File June-26'!$C$3:$L$670,8,0) -> 14 | I21: =VLOOKUP($A21,'Master File June-26'!$C$3:$L$670,9,0) -> 49.5 | J21: =VLOOKUP($A21,'Master File June-26'!$C$3:$L$670,10,0) -> 99 | K21: =IFERROR((J21/G21*30),0) -> 30 | L21: =IF(K21<H21,"ORDER NOW","IN STOCK") -> IN STOCK | M21: =IF(K21<H21,"CRITICAL","FOLLOW UP DELIVERY") -> FOLLOW UP DELIVERY | N21: 0
A22: RM-00434 | B22: Walnuts عين جمل | C22: 1 Box X 10 Kg | D22: Box | E22: 0.1 | F22: =VLOOKUP($A22,'Master File June-26'!$C$3:$L$670,6,0) -> 200 | G22: =VLOOKUP($A22,'Master File June-26'!$C$3:$L$670,7,0) -> 2000 | H22: =VLOOKUP($A22,'Master File June-26'!$C$3:$L$670,8,0) -> 14 | I22: =VLOOKUP($A22,'Master File June-26'!$C$3:$L$670,9,0) -> 1000 | J22: =VLOOKUP($A22,'Master File June-26'!$C$3:$L$670,10,0) -> 0 | K22: =IFERROR((J22/G22*30),0) -> 0 | L22: =IF(K22<H22,"ORDER NOW","IN STOCK") -> ORDER NOW | M22: =IF(K22<H22,"CRITICAL","FOLLOW UP DELIVERY") -> CRITICAL | N22: 0
A23: RM-00313 | B23: Vanilla bourbon فانيلا بوربون | C23: 1 Box X 12bottle X 1kg | D23: Box | E23: 0.083333333 | F23: =VLOOKUP($A23,'Master File June-26'!$C$3:$L$670,6,0) -> 250 | G23: =VLOOKUP($A23,'Master File June-26'!$C$3:$L$670,7,0) -> 3000 | H23: =VLOOKUP($A23,'Master File June-26'!$C$3:$L$670,8,0) -> 14 | I23: =VLOOKUP($A23,'Master File June-26'!$C$3:$L$670,9,0) -> 1500 | J23: =VLOOKUP($A23,'Master File June-26'!$C$3:$L$670,10,0) -> 0 | K23: =IFERROR((J23/G23*30),0) -> 0 | L23: =IF(K23<H23,"ORDER NOW","IN STOCK") -> ORDER NOW | M23: =IF(K23<H23,"CRITICAL","FOLLOW UP DELIVERY") -> CRITICAL | N23: 1
A24: RM-00293 | B24: Soft White Vanilla مسحوق فانيلا روبيكون | C24: 1 Box X 8 Bag X 1.5 Kg | D24: Box | E24: 0.083333333 | F24: =VLOOKUP($A24,'Master File June-26'!$C$3:$L$670,6,0) -> 77 | G24: =VLOOKUP($A24,'Master File June-26'!$C$3:$L$670,7,0) -> 924 | H24: =VLOOKUP($A24,'Master File June-26'!$C$3:$L$670,8,0) -> 14 | I24: =VLOOKUP($A24,'Master File June-26'!$C$3:$L$670,9,0) -> 462 | J24: =VLOOKUP($A24,'Master File June-26'!$C$3:$L$670,10,0) -> 0 | K24: =IFERROR((J24/G24*30),0) -> 0 | L24: =IF(K24<H24,"ORDER NOW","IN STOCK") -> ORDER NOW | M24: =IF(K24<H24,"CRITICAL","FOLLOW UP DELIVERY") -> CRITICAL | N24: 0
A25: RM-00458 | B25: Costa Rica San ignacio Coffee Breehant 1 KGكوستاريكا سان اجناسيو بريهانت 1kg | C25: KG | D25: Pcs | E25: 1 | F25: =VLOOKUP($A25,'Master File June-26'!$C$3:$L$670,6,0) -> 0 | G25: =VLOOKUP($A25,'Master File June-26'!$C$3:$L$670,7,0) -> 0 | H25: =VLOOKUP($A25,'Master File June-26'!$C$3:$L$670,8,0) -> 14 | I25: =VLOOKUP($A25,'Master File June-26'!$C$3:$L$670,9,0) -> 0 | J25: =VLOOKUP($A25,'Master File June-26'!$C$3:$L$670,10,0) -> 0 | K25: =IFERROR((J25/G25*30),0) -> 0 | L25: =IF(K25<H25,"ORDER NOW","IN STOCK") -> ORDER NOW | M25: =IF(K25<H25,"CRITICAL","FOLLOW UP DELIVERY") -> CRITICAL | N25: 1
A26: RM-00573 | B26: Syrup Giffard pomegranate سيروب رمان جيفارد | C26: 1 Box 6 Bottle X 1 Ltr | D26: Box | E26: 0.16666667 | F26: =VLOOKUP($A26,'Master File June-26'!$C$3:$L$670,6,0) -> 16.5 | G26: =VLOOKUP($A26,'Master File June-26'!$C$3:$L$670,7,0) -> 99 | H26: =VLOOKUP($A26,'Master File June-26'!$C$3:$L$670,8,0) -> 14 | I26: =VLOOKUP($A26,'Master File June-26'!$C$3:$L$670,9,0) -> 49.5 | J26: =VLOOKUP($A26,'Master File June-26'!$C$3:$L$670,10,0) -> 0 | K26: =IFERROR((J26/G26*30),0) -> 0 | L26: =IF(K26<H26,"ORDER NOW","IN STOCK") -> ORDER NOW | M26: =IF(K26<H26,"CRITICAL","FOLLOW UP DELIVERY") -> CRITICAL | N26: 0
A27: RM-00572 | B27: Syrup Giffard red raspberryسيروب توت احمر جيفراد | C27: 1 Box 6 Bottle X 1 Ltr | D27: Box | E27: 0.16666667 | F27: =VLOOKUP($A27,'Master File June-26'!$C$3:$L$670,6,0) -> 11 | G27: =VLOOKUP($A27,'Master File June-26'!$C$3:$L$670,7,0) -> 66 | H27: =VLOOKUP($A27,'Master File June-26'!$C$3:$L$670,8,0) -> 14 | I27: =VLOOKUP($A27,'Master File June-26'!$C$3:$L$670,9,0) -> 33 | J27: =VLOOKUP($A27,'Master File June-26'!$C$3:$L$670,10,0) -> 0 | K27: =IFERROR((J27/G27*30),0) -> 0 | L27: =IF(K27<H27,"ORDER NOW","IN STOCK") -> ORDER NOW | M27: =IF(K27<H27,"CRITICAL","FOLLOW UP DELIVERY") -> CRITICAL | N27: 0
A28: RM-00371 | B28: Fruits Puree Boiron Raspberry فواكة مهروسة بوارون - توت | C28: 1 PCS X 10 KG | D28: Pcs | E28: 0.1 | F28: =VLOOKUP($A28,'Master File June-26'!$C$3:$L$670,6,0) -> 0 | G28: =VLOOKUP($A28,'Master File June-26'!$C$3:$L$670,7,0) -> 0 | H28: =VLOOKUP($A28,'Master File June-26'!$C$3:$L$670,8,0) -> 14 | I28: =VLOOKUP($A28,'Master File June-26'!$C$3:$L$670,9,0) -> 0 | J28: =VLOOKUP($A28,'Master File June-26'!$C$3:$L$670,10,0) -> 0 | K28: =IFERROR((J28/G28*30),0) -> 0 | L28: =IF(K28<H28,"ORDER NOW","IN STOCK") -> ORDER NOW | M28: =IF(K28<H28,"CRITICAL","FOLLOW UP DELIVERY") -> CRITICAL | N28: 1
A29: RM-00100 | B29: FLORIMONT CREAM WHIPPING 35% FAT - FRANCE | كريمة خفق | C29: 1 Box X 12 Bottle X 1 ltr | D29: Box | E29: 0.083333333 | F29: =VLOOKUP($A29,'Master File June-26'!$C$3:$L$670,6,0) -> 66 | G29: =VLOOKUP($A29,'Master File June-26'!$C$3:$L$670,7,0) -> 792 | H29: =VLOOKUP($A29,'Master File June-26'!$C$3:$L$670,8,0) -> 14 | I29: =VLOOKUP($A29,'Master File June-26'!$C$3:$L$670,9,0) -> 396 | J29: =VLOOKUP($A29,'Master File June-26'!$C$3:$L$670,10,0) -> 0 | K29: =IFERROR((J29/G29*30),0) -> 0 | L29: =IF(K29<H29,"ORDER NOW","IN STOCK") -> ORDER NOW | M29: =IF(K29<H29,"CRITICAL","FOLLOW UP DELIVERY") -> CRITICAL | N29: 0
A30: RM-00642 | B30: Sponge chocolate Premix | خليط كيك شوكولاتة | C30: 1 Pcs X 25 KG | D30: Pcs | E30: 0.04 | F30: =VLOOKUP($A30,'Master File June-26'!$C$3:$L$670,6,0) -> 0 | G30: =VLOOKUP($A30,'Master File June-26'!$C$3:$L$670,7,0) -> 0 | H30: =VLOOKUP($A30,'Master File June-26'!$C$3:$L$670,8,0) -> 14 | I30: =VLOOKUP($A30,'Master File June-26'!$C$3:$L$670,9,0) -> 0 | J30: =VLOOKUP($A30,'Master File June-26'!$C$3:$L$670,10,0) -> 0 | K30: =IFERROR((J30/G30*30),0) -> 0 | L30: =IF(K30<H30,"ORDER NOW","IN STOCK") -> ORDER NOW | M30: =IF(K30<H30,"CRITICAL","FOLLOW UP DELIVERY") -> CRITICAL | N30: 1
A31: RM-00628 | B31: Slices cheddar cheese | جبن شدر سلايدر | C31: 200 Grm | D31: Pcs | E31: 5 | F31: =VLOOKUP($A31,'Master File June-26'!$C$3:$L$670,6,0) -> 500 | G31: =VLOOKUP($A31,'Master File June-26'!$C$3:$L$670,7,0) -> 100 | H31: =VLOOKUP($A31,'Master File June-26'!$C$3:$L$670,8,0) -> 14 | I31: =VLOOKUP($A31,'Master File June-26'!$C$3:$L$670,9,0) -> 50 | J31: =VLOOKUP($A31,'Master File June-26'!$C$3:$L$670,10,0) -> 0 | K31: =IFERROR((J31/G31*30),0) -> 0 | L31: =IF(K31<H31,"ORDER NOW","IN STOCK") -> ORDER NOW | M31: =IF(K31<H31,"CRITICAL","FOLLOW UP DELIVERY") -> CRITICAL | N31: 0
A32: RM-00253 | B32: Fresh yeast - خميرة فرش | C32: KG | D32: Pcs | E32: 1 | F32: =VLOOKUP($A32,'Master File June-26'!$C$3:$L$670,6,0) -> 0 | G32: =VLOOKUP($A32,'Master File June-26'!$C$3:$L$670,7,0) -> 0 | H32: =VLOOKUP($A32,'Master File June-26'!$C$3:$L$670,8,0) -> 14 | I32: =VLOOKUP($A32,'Master File June-26'!$C$3:$L$670,9,0) -> 0 | J32: =VLOOKUP($A32,'Master File June-26'!$C$3:$L$670,10,0) -> 0 | K32: =IFERROR((J32/G32*30),0) -> 0 | L32: =IF(K32<H32,"ORDER NOW","IN STOCK") -> ORDER NOW | M32: =IF(K32<H32,"CRITICAL","FOLLOW UP DELIVERY") -> CRITICAL | N32: 1
... A75: RM-00123 | B75: Bob Red Rice Flour طحين الرز | C75: 24*500 GRM | D75: KG | E75: 0.083333333 | F75: =VLOOKUP($A75,'Master File June-26'!$C$3:$L$670,6,0) -> 0 | G75: =VLOOKUP($A75,'Master File June-26'!$C$3:$L$670,7,0) -> 10 | H75: =VLOOKUP($A75,'Master File June-26'!$C$3:$L$670,8,0) -> 14 | I75: =VLOOKUP($A75,'Master File June-26'!$C$3:$L$670,9,0) -> 5 | J75: =VLOOKUP($A75,'Master File June-26'!$C$3:$L$670,10,0) -> 0 | K75: =IFERROR((J75/G75*30),0) -> 0 | L75: =IF(K75<H75,"ORDER NOW","IN STOCK") -> ORDER NOW | M75: =IF(K75<H75,"CRITICAL","FOLLOW UP DELIVERY") -> CRITICAL | N75: 0
A76: RM-00314 | B76: Vanilla Powder بودرة الفانيلا | C76: Pcs | E76: 1 | F76: =VLOOKUP($A76,'Master File June-26'!$C$3:$L$670,6,0) -> 0 | G76: =VLOOKUP($A76,'Master File June-26'!$C$3:$L$670,7,0) -> 2 | H76: =VLOOKUP($A76,'Master File June-26'!$C$3:$L$670,8,0) -> 14 | I76: =VLOOKUP($A76,'Master File June-26'!$C$3:$L$670,9,0) -> 1 | J76: =VLOOKUP($A76,'Master File June-26'!$C$3:$L$670,10,0) -> 0 | K76: =IFERROR((J76/G76*30),0) -> 0 | L76: =IF(K76<H76,"ORDER NOW","IN STOCK") -> ORDER NOW | M76: =IF(K76<H76,"CRITICAL","FOLLOW UP DELIVERY") -> CRITICAL | N76: 0
A77: RM-00328 | B77: Dried banana slices شرائح موز مجفف | C77: Pcs | E77: 1 | F77: =VLOOKUP($A77,'Master File June-26'!$C$3:$L$670,6,0) -> 0 | G77: =VLOOKUP($A77,'Master File June-26'!$C$3:$L$670,7,0) -> 30 | H77: =VLOOKUP($A77,'Master File June-26'!$C$3:$L$670,8,0) -> 14 | I77: =VLOOKUP($A77,'Master File June-26'!$C$3:$L$670,9,0) -> 15 | J77: =VLOOKUP($A77,'Master File June-26'!$C$3:$L$670,10,0) -> 0 | K77: =IFERROR((J77/G77*30),0) -> 0 | L77: =IF(K77<H77,"ORDER NOW","IN STOCK") -> ORDER NOW | M77: =IF(K77<H77,"CRITICAL","FOLLOW UP DELIVERY") -> CRITICAL | N77: 0
A78: RM-00318 | B78: INDOMIE - اندومي | C78: Box | D78: Box | E78: 1 | F78: =VLOOKUP($A78,'Master File June-26'!$C$3:$L$670,6,0) -> 25 | G78: =VLOOKUP($A78,'Master File June-26'!$C$3:$L$670,7,0) -> 25 | H78: =VLOOKUP($A78,'Master File June-26'!$C$3:$L$670,8,0) -> 14 | I78: =VLOOKUP($A78,'Master File June-26'!$C$3:$L$670,9,0) -> 12.5 | J78: =VLOOKUP($A78,'Master File June-26'!$C$3:$L$670,10,0) -> 0 | K78: =IFERROR((J78/G78*30),0) -> 0 | L78: =IF(K78<H78,"ORDER NOW","IN STOCK") -> ORDER NOW | M78: =IF(K78<H78,"CRITICAL","FOLLOW UP DELIVERY") -> CRITICAL | N78: 0
A79: RM-00329 | B79: Dried kiwi slices شرائح كيوي مجففة | C79: Pcs | E79: 1 | F79: =VLOOKUP($A79,'Master File June-26'!$C$3:$L$670,6,0) -> 0 | G79: =VLOOKUP($A79,'Master File June-26'!$C$3:$L$670,7,0) -> 20 | H79: =VLOOKUP($A79,'Master File June-26'!$C$3:$L$670,8,0) -> 14 | I79: =VLOOKUP($A79,'Master File June-26'!$C$3:$L$670,9,0) -> 10 | J79: =VLOOKUP($A79,'Master File June-26'!$C$3:$L$670,10,0) -> 0 | K79: =IFERROR((J79/G79*30),0) -> 0 | L79: =IF(K79<H79,"ORDER NOW","IN STOCK") -> ORDER NOW | M79: =IF(K79<H79,"CRITICAL","FOLLOW UP DELIVERY") -> CRITICAL | N79: 0
A80: RM-00208 | B80: Cardamom Whole JAMBO هيل اخضر | C80: KG | D80: Pcs | E80: 1 | F80: =VLOOKUP($A80,'Master File June-26'!$C$3:$L$670,6,0) -> 5 | G80: =VLOOKUP($A80,'Master File June-26'!$C$3:$L$670,7,0) -> 5 | H80: =VLOOKUP($A80,'Master File June-26'!$C$3:$L$670,8,0) -> 14 | I80: =VLOOKUP($A80,'Master File June-26'!$C$3:$L$670,9,0) -> 2.5 | J80: =VLOOKUP($A80,'Master File June-26'!$C$3:$L$670,10,0) -> 0 | K80: =IFERROR((J80/G80*30),0) -> 0 | L80: =IF(K80<H80,"ORDER NOW","IN STOCK") -> ORDER NOW | M80: =IF(K80<H80,"CRITICAL","FOLLOW UP DELIVERY") -> CRITICAL | N80: 0
A81: RM-00148 | B81: Clove قرنفل | C81: KG | D81: Pcs | E81: 1 | F81: =VLOOKUP($A81,'Master File June-26'!$C$3:$L$670,6,0) -> 1 | G81: =VLOOKUP($A81,'Master File June-26'!$C$3:$L$670,7,0) -> 1 | H81: =VLOOKUP($A81,'Master File June-26'!$C$3:$L$670,8,0) -> 14 | I81: =VLOOKUP($A81,'Master File June-26'!$C$3:$L$670,9,0) -> 0.5 | J81: =VLOOKUP($A81,'Master File June-26'!$C$3:$L$670,10,0) -> 0 | K81: =IFERROR((J81/G81*30),0) -> 0 | L81: =IF(K81<H81,"ORDER NOW","IN STOCK") -> ORDER NOW | M81: =IF(K81<H81,"CRITICAL","FOLLOW UP DELIVERY") -> CRITICAL | N81: 0
A82: RM-00019 | B82: Blue Cheese جبن ازرق | C82: KG | D82: Pcs | E82: 1 | F82: =VLOOKUP($A82,'Master File June-26'!$C$3:$L$670,6,0) -> 10 | G82: =VLOOKUP($A82,'Master File June-26'!$C$3:$L$670,7,0) -> 10 | H82: =VLOOKUP($A82,'Master File June-26'!$C$3:$L$670,8,0) -> 14 | I82: =VLOOKUP($A82,'Master File June-26'!$C$3:$L$670,9,0) -> 5 | J82: =VLOOKUP($A82,'Master File June-26'!$C$3:$L$670,10,0) -> 0 | K82: =IFERROR((J82/G82*30),0) -> 0 | L82: =IF(K82<H82,"ORDER NOW","IN STOCK") -> ORDER NOW | M82: =IF(K82<H82,"CRITICAL","FOLLOW UP DELIVERY") -> CRITICAL | N82: 0
A83: RM-00017 | B83: جبن موزريلا مبشورة Mozzarella cheese shredded | C83: KG | D83: Pcs | E83: 1 | F83: =VLOOKUP($A83,'Master File June-26'!$C$3:$L$670,6,0) -> 15 | G83: =VLOOKUP($A83,'Master File June-26'!$C$3:$L$670,7,0) -> 15 | H83: =VLOOKUP($A83,'Master File June-26'!$C$3:$L$670,8,0) -> 14 | I83: =VLOOKUP($A83,'Master File June-26'!$C$3:$L$670,9,0) -> 7.5 | J83: =VLOOKUP($A83,'Master File June-26'!$C$3:$L$670,10,0) -> 0 | K83: =IFERROR((J83/G83*30),0) -> 0 | L83: =IF(K83<H83,"ORDER NOW","IN STOCK") -> ORDER NOW | M83: =IF(K83<H83,"CRITICAL","FOLLOW UP DELIVERY") -> CRITICAL | N83: 0
...

Sheet Packiging Materila Stock Status
B2: Item Code | C2: Item Description | D2: Packing | E2: UOM | F2: Conversion | G2: QTY in Pack | H2: QTY in Unit | I2: Lead Time | J2: Reordering Point | K2: WH Stocks | L2: Coverage/Day | M2: 0rder Status | N2: Criticality | O2: Stock Status
A3: 11 | B3: PM-00568 | C3: كيس مخبوزات مطبوع مقاس 10 × 14.5 cm (نمق)-Printed Bakery Paper Bag, 10 × 14.5 cm(Namq) | D3: 1Box X 8000 | E3: Box | F3: 0.000125 | G3: 8 | H3: 64000 | I3: 14 | J3: 32000 | K3: 0 | L3: =IFERROR((K3/H3*30),0) -> 0 | M3: ORDER NOW | N3: CRITICAL | O3: 0
A4: 19 | B4: PM-00075 | C4: Nozzle Lids for Coffee Box 1 Ltr أغطية كرتون القهوة سعة 1 لتر | D4: 1Box X 400 | E4: Box | F4: 0.0025 | G4: 0 | H4: 0 | I4: 14 | J4: 0 | K4: 0 | L4: =IFERROR((K4/H4*30),0) -> 0 | M4: ORDER NOW | N4: CRITICAL | O4: 1
A5: 29 | B5: PM-00563 | C5: Paper Cup Surprise 16 oz - Outer كوب ورقي للمفاجأة 16 أونص نمق | D5: 1 Box X 1000 Pcs. | E5: Box | F5: 0.001 | G5: 0 | H5: 0 | I5: 60 | J5: 0 | K5: 197000 | L5: =IFERROR((K5/H5*30),0) -> 0 | M5: ORDER NOW | N5: CRITICAL | O5: 1
A6: 46 | B6: PM-00436 | C6: استيكر هوت شوكلت Hot chocolate sticker | E6: Box | F6: 1 | G6: 5.5 | H6: 5.5 | I6: 14 | J6: 2.75 | K6: 0 | L6: =IFERROR((K6/H6*30),0) -> 0 | M6: ORDER NOW | N6: CRITICAL | O6: 0
A7: 49 | B7: PM-00230 | C7: Cafec V60 Filter 01 Coffee Filter كافيك فلاتر ترشيح ورقية - مقاس 01 | D7: 1 Box X 80 Case X 100 PCS | E7: Box | F7: 0.000125 | G7: 0 | H7: 0 | I7: 14 | J7: 0 | K7: 56000 | L7: =IFERROR((K7/H7*30),0) -> 0 | M7: ORDER NOW | N7: CRITICAL | O7: 1
A8: 50 | B8: PM-00240 | C8: Cold Brew Filter فلتر كولد برو خفيف | D8: 1 Pcs | E8: Pcs | F8: 1 | G8: 44 | H8: 44 | I8: 14 | J8: 22 | K8: 0 | L8: =IFERROR((K8/H8*30),0) -> 0 | M8: ORDER NOW | N8: CRITICAL | O8: 0
A9: 53 | B9: PM-00655 | C9: سليف زجاجة ايس تي | Glass sleeve for iced | D9: 1 Box X 600 Pcs | E9: Box | F9: 0.0016666667 | G9: 20 | H9: 12000 | I9: 14 | J9: 6000 | K9: 0 | L9: =IFERROR((K9/H9*30),0) -> 0 | M9: ORDER NOW | N9: CRITICAL | O9: 0
A10: 55 | B10: PM-00656 | C10: سليف زجاجة كولدر برو | Glass sleeve for cold bro | D10: 1 Box X1200 Pcs | E10: Box | F10: 0.00083333333 | G10: 10 | H10: 12000 | I10: 14 | J10: 6000 | K10: 0 | L10: =IFERROR((K10/H10*30),0) -> 0 | M10: ORDER NOW | N10: CRITICAL | O10: 0
A11: 56 | B11: PM-00533 | C11: كوب فخار 110 ملي محفور عليى شعار من الداخل والخارج قليز شفاف مطفي (لتقديم الاسبريسو) | D11: Pcs. | E11: Pcs | F11: 1 | G11: 0 | H11: 0 | I11: 30 | J11: 0 | K11: 16 | L11: =IFERROR((K11/H11*30),0) -> 0 | M11: ORDER NOW | N11: CRITICAL | O11: 1
A12: 57 | B12: PM-00527 | C12: كوب فخار 200 مل - محفور بشعار من الخارج - قليز شفاف لامع من الداخل والخارج | D12: Pcs. | E12: Pcs | F12: 1 | G12: 0 | H12: 0 | I12: 30 | J12: 0 | K12: 531 | L12: =IFERROR((K12/H12*30),0) -> 0 | M12: ORDER NOW | N12: CRITICAL | O12: 1
A13: 58 | B13: PM-00528 | C13: كوب فخار 200 مل - محفور بشعار من الداخل والخارج - قليز شفاف مطفي | D13: Pcs. | E13: Pcs | F13: 1 | G13: 0 | H13: 0 | I13: 30 | J13: 0 | K13: 0 | L13: =IFERROR((K13/H13*30),0) -> 0 | M13: ORDER NOW | N13: CRITICAL | O13: 1
A14: 59 | B14: PM-00530 | C14: كوب فخار 300 مل - محفور عليه شعار من الداخل والخارج - قليز شفاف مطفي - STONEWARE | D14: Pcs. | E14: Pcs | F14: 1 | G14: 0 | H14: 0 | I14: 30 | J14: 0 | K14: 0 | L14: =IFERROR((K14/H14*30),0) -> 0 | M14: ORDER NOW | N14: CRITICAL | O14: 1
A15: 60 | B15: PM-00534 | C15: صحن فخار مقاس 20*20*15 محفور عليه الشعار في المنتصف | D15: Pcs. | E15: Pcs | F15: 1 | G15: 0 | H15: 0 | I15: 30 | J15: 0 | K15: 2 | L15: =IFERROR((K15/H15*30),0) -> 0 | M15: ORDER NOW | N15: CRITICAL | O15: 1
A16: 64 | B16: PM-00139 | C16: كرت الاسبريسو نمق (سان اجناسيو) Espresso card (San Ignacio) | D16: 1 Bundle X 500 pcs | E16: bundel | F16: 0.002 | G16: 5.5 | H16: 2750 | I16: 14 | J16: 1375 | K16: 0 | L16: =IFERROR((K16/H16*30),0) -> 0 | M16: ORDER NOW | N16: CRITICAL | O16: 0
A17: 65 | B17: PM-00295 | C17: Customer Evaluation Card كرت تقييم العملاء ( نمق ) | D17: 1 Box X 1000 | E17: Box | F17: 0.001 | G17: 0 | H17: 0 | I17: 14 | J17: 0 | K17: 0 | L17: =IFERROR((K17/H17*30),0) -> 0 | M17: ORDER NOW | N17: CRITICAL | O17: 1
A18: 66 | B18: PM-00276 | C18: Tape شطرطون | D18: 1 Box X 24 Pcs | E18: Box | F18: 0.041666667 | G18: 5.5 | H18: 132 | I18: 14 | J18: 66 | K18: 0 | L18: =IFERROR((K18/H18*30),0) -> 0 | M18: ORDER NOW | N18: CRITICAL | O18: 0
A19: 68 | B19: PM-00277 | C19: knife ( NAMQ ) سكين ( نمق ) | D19: 1 Box X 500 Pcs. | E19: Box | F19: 0.002 | G19: 38.5 | H19: 19250 | I19: 14 | J19: 9625 | K19: 0 | L19: =IFERROR((K19/H19*30),0) -> 0 | M19: ORDER NOW | N19: CRITICAL | O19: 0
A20: 69 | B20: PM-00448 | C20: Sticker Date ستيكر التاريخ | F20: 1 | G20: 5.5 | H20: 5.5 | I20: 14 | J20: 2.75 | K20: 0 | L20: =IFERROR((K20/H20*30),0) -> 0 | M20: ORDER NOW | N20: CRITICAL | O20: 0
A21: 70 | B21: PM-00261 | C21: Baking Paper 60*40 ورق خبازة 60*40 | D21: 1 Box X 500 Pcs. / 1 Box X 1000 Pcs. | E21: Box | F21: 0.002 | G21: 100 | H21: 50000 | I21: 14 | J21: 25000 | K21: 0 | L21: =IFERROR((K21/H21*30),0) -> 0 | M21: ORDER NOW | N21: CRITICAL | O21: 0
A22: 71 | B22: PM-00263 | C22: Cling Film رول تغليف نايلون | D22: Pcs. | E22: Pcs | F22: 1 | G22: 400 | H22: 400 | I22: 14 | J22: 200 | K22: 0 | L22: =IFERROR((K22/H22*30),0) -> 0 | M22: ORDER NOW | N22: CRITICAL | O22: 0
A23: 72 | B23: PM-00341 | C23: Point of sale roll - رول نقاط البيع | D23: 1 Box X 50 Pcs | E23: Box | F23: 0.02 | G23: 11 | H23: 550 | I23: 14 | J23: 275 | K23: 0 | L23: =IFERROR((K23/H23*30),0) -> 0 | M23: ORDER NOW | N23: CRITICAL | O23: 0
A24: 73 | B24: PM-00586 | C24: Namq Thermal Stainless Steel Cup with Two Lids – Sky Blue Color | D24: Pcs. | E24: Pcs | F24: 1 | G24: 0 | H24: 0 | I24: 60 | J24: 0 | K24: 485 | L24: =IFERROR((K24/H24*30),0) -> 0 | M24: ORDER NOW | N24: CRITICAL | O24: 1
A25: 74 | B25: PM-00582 | C25: Namq Thermal Stainless Steel Cup with Two Lids – Olive Green Color | D25: Pcs. | E25: Pcs | F25: 1 | G25: 0 | H25: 0 | I25: 60 | J25: 0 | K25: 413 | L25: =IFERROR((K25/H25*30),0) -> 0 | M25: ORDER NOW | N25: CRITICAL | O25: 1
A26: 75 | B26: PM-00583 | C26: Namq Thermal Stainless Steel Cup with Two Lids - Burgundy Color | D26: Pcs. | E26: Pcs | F26: 1 | G26: 0 | H26: 0 | I26: 60 | J26: 0 | K26: 241 | L26: =IFERROR((K26/H26*30),0) -> 0 | M26: ORDER NOW | N26: CRITICAL | O26: 1
A27: 76 | B27: PM-00584 | C27: Namq Thermal Stainless Steel Cup with Two Lids – Beige Color | D27: Pcs. | E27: Pcs | F27: 1 | G27: 0 | H27: 0 | I27: 60 | J27: 0 | K27: 205 | L27: =IFERROR((K27/H27*30),0) -> 0 | M27: ORDER NOW | N27: CRITICAL | O27: 1
A28: 77 | B28: PM-00585 | C28: Thermal Stainless Steel Cup with Two Lids – Navy Blue | D28: Pcs. | E28: Pcs | F28: 1 | G28: 0 | H28: 0 | I28: 60 | J28: 0 | K28: 613 | L28: =IFERROR((K28/H28*30),0) -> 0 | M28: ORDER NOW | N28: CRITICAL | O28: 1
A29: 90 | B29: PM-00182 | C29: Breehant Paper cup 6.5 OZ كوب ورقي 6.5 اونص بريهانت | D29: 1 Box 20 Pack X 25 Pcs | E29: Box | F29: 0.002 | G29: 150 | H29: 75000 | I29: 14 | J29: 37500 | K29: 0 | L29: =IFERROR((K29/H29*30),0) -> 0 | M29: ORDER NOW | N29: CRITICAL | O29: 0
A30: 93 | B30: PM-00653 | C30: Cup 7 oz double wide Seasnal ( Breehant ) - كوب 7 اونص دبل فتحة واسعه موسمى ( بريهانت ) | D30: 1 Box 20 Pack X 25 Pcs | E30: Box | F30: 0.002 | G30: 8 | H30: 4000 | I30: 14 | J30: 2000 | K30: 0 | L30: =IFERROR((K30/H30*30),0) -> 0 | M30: ORDER NOW | N30: CRITICAL | O30: 0
A31: 94 | B31: PM-00200 | C31: Season Paper cup Double 12 Oz ( BREEHANT ) كوب ورقي 12 اونصه تصميم موسمي ( بريهانت ) | D31: 1 Box X 500 | E31: Box | F31: 0.002 | G31: 8 | H31: 4000 | I31: 14 | J31: 2000 | K31: 0 | L31: =IFERROR((K31/H31*30),0) -> 0 | M31: ORDER NOW | N31: CRITICAL | O31: 0
A32: 95 | B32: PM-00201 | C32: Season Paper cup Double 9 Oz ( BREEHANT ) كوب ورقي 9 اونصه تصميم موسمي ( بريهانت ) | D32: 1 Box X 1000 Pcs | E32: Box | F32: 0.001 | G32: 0 | H32: 0 | I32: 14 | J32: 0 | K32: 0 | L32: =IFERROR((K32/H32*30),0) -> 0 | M32: ORDER NOW | N32: CRITICAL | O32: 1
... A45: 123 | B45: PM-00080 | C45: Bar Box (NAMQ)بوكس البارات (نمق) | D45: 1 bundle X 500 PCS | E45: bundel | F45: 0.002 | G45: 15 | H45: 7500 | I45: 14 | J45: 3750 | K45: 0 | L45: =IFERROR((K45/H45*30),0) -> 0 | M45: ORDER NOW | N45: CRITICAL | O45: 0
A46: 125 | B46: PM-00093 | C46: Hallomi Sandwiche Box بوكس ساندويتش حلومي | D46: Pcs | F46: 1 | G46: 0 | H46: 0 | I46: 14 | J46: 0 | K46: 0 | L46: =IFERROR((K46/H46*30),0) -> 0 | M46: ORDER NOW | N46: CRITICAL | O46: 1
A47: 127 | B47: PM-00076 | C47: Salted caramel box بوكس كراميل مملح | D47: 1 bundle X 100 PCS | E47: bundel | F47: 0.01 | G47: 300 | H47: 30000 | I47: 14 | J47: 15000 | K47: 0 | L47: =IFERROR((K47/H47*30),0) -> 0 | M47: ORDER NOW | N47: CRITICAL | O47: 0
A48: 129 | B48: PM-00105 | C48: Crunchy Chocolate box (BREEHANT) بوكس كرانشي شوكلت ( بريهانت ) | D48: 1 Box X 200 Pcs | E48: Box | F48: 0.005 | G48: 50 | H48: 10000 | I48: 14 | J48: 5000 | K48: 0 | L48: =IFERROR((K48/H48*30),0) -> 0 | M48: ORDER NOW | N48: CRITICAL | O48: 0
A49: 136 | B49: PM-00330 | C49: Transfer Chocolate Paper ( Breehant ) ورق ترانسفير التشوكلت ( بريهانت ) | D49: 1 Bundle X 50 Pcs. | E49: bundel | F49: 0.02 | G49: 0 | H49: 0 | I49: 14 | J49: 0 | K49: 0 | L49: =IFERROR((K49/H49*30),0) -> 0 | M49: ORDER NOW | N49: CRITICAL | O49: 1
A50: 141 | B50: PM-00617 | C50: كوب ابيض سراميك + صحن 8 اونص White ceramic plate with sauce | D50: Pcs | E50: Pcs | F50: 1 | G50: 0 | H50: 0 | I50: 14 | J50: 0 | K50: 0 | L50: =IFERROR((K50/H50*30),0) -> 0 | M50: ORDER NOW | N50: CRITICAL | O50: 1
A51: 143 | B51: PM-00686 | C51: بوكس البار مارشميلو|| Marshmallow Bar Box | D51: Pcs | E51: Pcs | F51: 1 | G51: 0 | H51: 0 | I51: 14 | J51: 0 | K51: 0 | L51: =IFERROR((K51/H51*30),0) -> 0 | M51: ORDER NOW | N51: CRITICAL | O51: 1
A52: 144 | B52: PM-00688 | C52: سليف مارشميلو كراميل||Marshmallow Caramel Sleeve | D52: Pcs | E52: Pcs | F52: 1 | G52: 0 | H52: 0 | I52: 14 | J52: 0 | K52: 0 | L52: =IFERROR((K52/H52*30),0) -> 0 | M52: ORDER NOW | N52: CRITICAL | O52: 1
A53: 145 | B53: PM-00687 | C53: سليف مارشميلو كرانشي||Marshmallow Crunchy Sleeve | D53: Pcs | E53: Pcs | F53: 1 | G53: 0 | H53: 0 | I53: 14 | J53: 0 | K53: 0 | L53: =IFERROR((K53/H53*30),0) -> 0 | M53: ORDER NOW | N53: CRITICAL | O53: 1
...

Sheet Consumables Stock Status
